[2025-06-04T02:59:31.475+0000] {local_task_job_runner.py:123} INFO - ::group::Pre task execution logs
[2025-06-04T02:59:31.489+0000] {taskinstance.py:2612} INFO - Dependencies all met for dep_context=non-requeueable deps ti=<TaskInstance: run_jar_dag.run_jar scheduled__2025-06-03T00:00:00+00:00 [queued]>
[2025-06-04T02:59:31.495+0000] {taskinstance.py:2612} INFO - Dependencies all met for dep_context=requeueable deps ti=<TaskInstance: run_jar_dag.run_jar scheduled__2025-06-03T00:00:00+00:00 [queued]>
[2025-06-04T02:59:31.495+0000] {taskinstance.py:2865} INFO - Starting attempt 1 of 1
[2025-06-04T02:59:31.506+0000] {taskinstance.py:2888} INFO - Executing <Task(BashOperator): run_jar> on 2025-06-03 00:00:00+00:00
[2025-06-04T02:59:31.516+0000] {logging_mixin.py:190} WARNING - /home/***/.local/lib/python3.12/site-packages/***/task/task_runner/standard_task_runner.py:70 DeprecationWarning: This process (pid=26031) is multi-threaded, use of fork() may lead to deadlocks in the child.
[2025-06-04T02:59:31.517+0000] {standard_task_runner.py:72} INFO - Started process 26032 to run task
[2025-06-04T02:59:31.516+0000] {standard_task_runner.py:104} INFO - Running: ['***', 'tasks', 'run', 'run_jar_dag', 'run_jar', 'scheduled__2025-06-03T00:00:00+00:00', '--job-id', '307', '--raw', '--subdir', 'DAGS_FOLDER/Sesion5/DAG_Jar.py', '--cfg-path', '/tmp/tmpx6xlxbe_']
[2025-06-04T02:59:31.518+0000] {standard_task_runner.py:105} INFO - Job 307: Subtask run_jar
[2025-06-04T02:59:31.531+0000] {logging_mixin.py:190} WARNING - /home/***/.local/lib/python3.12/site-packages/***/settings.py:209 DeprecationWarning: The sql_alchemy_conn option in [core] has been moved to the sql_alchemy_conn option in [database] - the old setting has been used, but please update your config.
[2025-06-04T02:59:31.558+0000] {task_command.py:467} INFO - Running <TaskInstance: run_jar_dag.run_jar scheduled__2025-06-03T00:00:00+00:00 [running]> on host 31d54648d280
[2025-06-04T02:59:31.560+0000] {logging_mixin.py:190} WARNING - /home/***/.local/lib/python3.12/site-packages/***/settings.py:470 DeprecationWarning: The sql_alchemy_conn option in [core] has been moved to the sql_alchemy_conn option in [database] - the old setting has been used, but please update your config.
[2025-06-04T02:59:31.627+0000] {taskinstance.py:3131} INFO - Exporting env vars: AIRFLOW_CTX_DAG_OWNER='***' AIRFLOW_CTX_DAG_ID='run_jar_dag' AIRFLOW_CTX_TASK_ID='run_jar' AIRFLOW_CTX_EXECUTION_DATE='2025-06-03T00:00:00+00:00' AIRFLOW_CTX_TRY_NUMBER='1' AIRFLOW_CTX_DAG_RUN_ID='scheduled__2025-06-03T00:00:00+00:00'
[2025-06-04T02:59:31.628+0000] {taskinstance.py:731} INFO - ::endgroup::
[2025-06-04T02:59:31.644+0000] {subprocess.py:63} INFO - Tmp dir root location: /tmp
[2025-06-04T02:59:31.644+0000] {subprocess.py:75} INFO - Running command: ['/usr/bin/bash', '-c', 'java -jar /opt/***/dags/Sesion5/data/HolaMundoDatapath.jar']
[2025-06-04T02:59:31.654+0000] {subprocess.py:86} INFO - Output:
[2025-06-04T02:59:31.711+0000] {subprocess.py:93} INFO - /usr/bin/bash: line 1: java: command not found
[2025-06-04T02:59:31.711+0000] {subprocess.py:97} INFO - Command exited with return code 127
[2025-06-04T02:59:31.721+0000] {taskinstance.py:3310} ERROR - Task failed with exception
Traceback (most recent call last):
  File "/home/airflow/.local/lib/python3.12/site-packages/airflow/models/taskinstance.py", line 767, in _execute_task
    result = _execute_callable(context=context, **execute_callable_kwargs)
             ^^^^^^^^^^^^^^^^^^^^^^^^^^^^^^^^^^^^^^^^^^^^^^^^^^^^^^^^^^^^^
  File "/home/airflow/.local/lib/python3.12/site-packages/airflow/models/taskinstance.py", line 733, in _execute_callable
    return ExecutionCallableRunner(
           ^^^^^^^^^^^^^^^^^^^^^^^^
  File "/home/airflow/.local/lib/python3.12/site-packages/airflow/utils/operator_helpers.py", line 252, in run
    return self.func(*args, **kwargs)
           ^^^^^^^^^^^^^^^^^^^^^^^^^^
  File "/home/airflow/.local/lib/python3.12/site-packages/airflow/models/baseoperator.py", line 406, in wrapper
    return func(self, *args, **kwargs)
           ^^^^^^^^^^^^^^^^^^^^^^^^^^^
  File "/home/airflow/.local/lib/python3.12/site-packages/airflow/operators/bash.py", line 249, in execute
    raise AirflowException(
airflow.exceptions.AirflowException: Bash command failed. The command returned a non-zero exit code 127.
[2025-06-04T02:59:31.729+0000] {taskinstance.py:1225} INFO - Marking task as FAILED. dag_id=run_jar_dag, task_id=run_jar, run_id=scheduled__2025-06-03T00:00:00+00:00, execution_date=20250603T000000, start_date=20250604T025931, end_date=20250604T025931
[2025-06-04T02:59:31.739+0000] {taskinstance.py:340} INFO - ::group::Post task execution logs
[2025-06-04T02:59:31.739+0000] {standard_task_runner.py:124} ERROR - Failed to execute job 307 for task run_jar (Bash command failed. The command returned a non-zero exit code 127.; 26032)
Traceback (most recent call last):
  File "/home/airflow/.local/lib/python3.12/site-packages/airflow/task/task_runner/standard_task_runner.py", line 117, in _start_by_fork
    ret = args.func(args, dag=self.dag)
          ^^^^^^^^^^^^^^^^^^^^^^^^^^^^^
  File "/home/airflow/.local/lib/python3.12/site-packages/airflow/cli/cli_config.py", line 49, in command
    return func(*args, **kwargs)
           ^^^^^^^^^^^^^^^^^^^^^
  File "/home/airflow/.local/lib/python3.12/site-packages/airflow/utils/cli.py", line 115, in wrapper
    return f(*args, **kwargs)
           ^^^^^^^^^^^^^^^^^^
  File "/home/airflow/.local/lib/python3.12/site-packages/airflow/cli/commands/task_command.py", line 483, in task_run
    task_return_code = _run_task_by_selected_method(args, _dag, ti)
                       ^^^^^^^^^^^^^^^^^^^^^^^^^^^^^^^^^^^^^^^^^^^^
  File "/home/airflow/.local/lib/python3.12/site-packages/airflow/cli/commands/task_command.py", line 256, in _run_task_by_selected_method
    return _run_raw_task(args, ti)
           ^^^^^^^^^^^^^^^^^^^^^^^
  File "/home/airflow/.local/lib/python3.12/site-packages/airflow/cli/commands/task_command.py", line 341, in _run_raw_task
    return ti._run_raw_task(
           ^^^^^^^^^^^^^^^^^
  File "/home/airflow/.local/lib/python3.12/site-packages/airflow/utils/session.py", line 97, in wrapper
    return func(*args, session=session, **kwargs)
           ^^^^^^^^^^^^^^^^^^^^^^^^^^^^^^^^^^^^^^
  File "/home/airflow/.local/lib/python3.12/site-packages/airflow/models/taskinstance.py", line 3004, in _run_raw_task
    return _run_raw_task(
           ^^^^^^^^^^^^^^
  File "/home/airflow/.local/lib/python3.12/site-packages/airflow/models/taskinstance.py", line 273, in _run_raw_task
    TaskInstance._execute_task_with_callbacks(
  File "/home/airflow/.local/lib/python3.12/site-packages/airflow/models/taskinstance.py", line 3158, in _execute_task_with_callbacks
    result = self._execute_task(context, task_orig)
             ^^^^^^^^^^^^^^^^^^^^^^^^^^^^^^^^^^^^^^
  File "/home/airflow/.local/lib/python3.12/site-packages/airflow/models/taskinstance.py", line 3182, in _execute_task
    return _execute_task(self, context, task_orig)
           ^^^^^^^^^^^^^^^^^^^^^^^^^^^^^^^^^^^^^^^
  File "/home/airflow/.local/lib/python3.12/site-packages/airflow/models/taskinstance.py", line 767, in _execute_task
    result = _execute_callable(context=context, **execute_callable_kwargs)
             ^^^^^^^^^^^^^^^^^^^^^^^^^^^^^^^^^^^^^^^^^^^^^^^^^^^^^^^^^^^^^
  File "/home/airflow/.local/lib/python3.12/site-packages/airflow/models/taskinstance.py", line 733, in _execute_callable
    return ExecutionCallableRunner(
           ^^^^^^^^^^^^^^^^^^^^^^^^
  File "/home/airflow/.local/lib/python3.12/site-packages/airflow/utils/operator_helpers.py", line 252, in run
    return self.func(*args, **kwargs)
           ^^^^^^^^^^^^^^^^^^^^^^^^^^
  File "/home/airflow/.local/lib/python3.12/site-packages/airflow/models/baseoperator.py", line 406, in wrapper
    return func(self, *args, **kwargs)
           ^^^^^^^^^^^^^^^^^^^^^^^^^^^
  File "/home/airflow/.local/lib/python3.12/site-packages/airflow/operators/bash.py", line 249, in execute
    raise AirflowException(
airflow.exceptions.AirflowException: Bash command failed. The command returned a non-zero exit code 127.
[2025-06-04T02:59:31.773+0000] {local_task_job_runner.py:266} INFO - Task exited with return code 1
[2025-06-04T02:59:31.787+0000] {taskinstance.py:3900} INFO - 0 downstream tasks scheduled from follow-on schedule check
[2025-06-04T02:59:31.788+0000] {local_task_job_runner.py:245} INFO - ::endgroup::
